<?xml version="1.0"?>
<!-- this file was autogenerated by bender blender xacro exporter -->


<robot name="suzanne_bot" xmlns:xacro="http://ros.org/wiki/xacro">

<link name="base_footprint">
    <!-- visual -->
    
    
    <!-- collision -->
    

    <!-- inertial -->
    
        <inertial>
        <origin xyz="0 0 0" rpy="0 0 0" />
        <mass value="1.5"/>
        <inertia 
            ixx="1.5" ixy="0.0" ixz="0.0" 
            iyy="1.5" iyz="0.0" 
            izz="1.5"/>
        </inertial>
    
</link>

<link name="base_link">
    <!-- visual -->
    
    <visual>
        
        <geometry>
            <mesh filename="package://suzanne_robot_description/meshes/chassi.dae"/>
        </geometry>
    </visual>

    
    <!-- collision -->
    
    <collision>
        
        <geometry>
            <mesh filename="package://suzanne_robot_description/meshes/chassi.dae"/>
        </geometry>
    </collision>

    <!-- inertial -->
    
        <inertial>
        <origin xyz="0 0 0" rpy="0 0 0" />
        <mass value="1000"/>
        <inertia 
            ixx="1.5" ixy="0.0" ixz="0.0" 
            iyy="1.5" iyz="0.0" 
            izz="1.5"/>
        </inertial>
    
</link>

<joint name="base_footprint_base_link_joint" type="revolute">
    <parent link="base_footprint"/>
    <child link="base_link"/>
    
      <origin xyz="  0.0000   0.0000   1.0607" rpy="  0.0000  -0.0000   0.0000" />

    <axis xyz="1 0 0"/>
    <!-- 
        THIS is a dirty hack must be fixed in future versions
        what we need is a new empty type which has properties for joint types limits...
        lower and upper could be set by constraints    
    -->
    <limit effort="0" velocity="0" lower="0" upper="0" />
  </joint> 
 
   <transmission name="base_footprint_base_link_trans">
      <type>transmission_interface/SimpleTransmission</type>
      <joint name="base_footprint_base_link_joint"/>
      <actuator name="base_footprint_base_link_motor">
          <hardwareInterface>PositionJointInterface</hardwareInterface>
         <mechanicalReduction>1</mechanicalReduction>
       </actuator>
  </transmission>

<link name="head_link">
    <!-- visual -->
    
    <visual>
        
        <geometry>
            <mesh filename="package://suzanne_robot_description/meshes/head.dae"/>
        </geometry>
    </visual>

    
    <!-- collision -->
    
    <collision>
        
        <geometry>
            <mesh filename="package://suzanne_robot_description/meshes/head.dae"/>
        </geometry>
    </collision>

    <!-- inertial -->
    
        <inertial>
        <origin xyz="0 0 0" rpy="0 0 0" />
        <mass value="10"/>
        <inertia 
            ixx="1.5" ixy="0.0" ixz="0.0" 
            iyy="1.5" iyz="0.0" 
            izz="1.5"/>
        </inertial>
    
</link>

<joint name="base_link_head_link_joint" type="revolute">
    <parent link="base_link"/>
    <child link="head_link"/>
    
      <origin xyz="  2.7640   0.0000   3.9750" rpy="  0.0000  -0.0000   0.0000" />

    <axis xyz="1 0 0"/>
    <!-- 
        THIS is a dirty hack must be fixed in future versions
        what we need is a new empty type which has properties for joint types limits...
        lower and upper could be set by constraints    
    -->
    <limit effort="0" velocity="0" lower="0" upper="0" />
  </joint> 
 
   <transmission name="base_link_head_link_trans">
      <type>transmission_interface/SimpleTransmission</type>
      <joint name="base_link_head_link_joint"/>
      <actuator name="base_link_head_link_motor">
          <hardwareInterface>PositionJointInterface</hardwareInterface>
         <mechanicalReduction>1</mechanicalReduction>
       </actuator>
  </transmission>

<link name="Eye_left">
    <!-- visual -->
    
    <visual>
        
        <geometry>
            <mesh filename="package://suzanne_robot_description/meshes/eye.dae"/>
        </geometry>
    </visual>

    
    <!-- collision -->
    
    <collision>
        
        <geometry>
            <mesh filename="package://suzanne_robot_description/meshes/eye.dae"/>
        </geometry>
    </collision>

    <!-- inertial -->
    
        <inertial>
        <origin xyz="0 0 0" rpy="0 0 0" />
        <mass value="1.5"/>
        <inertia 
            ixx="1.5" ixy="0.0" ixz="0.0" 
            iyy="1.5" iyz="0.0" 
            izz="1.5"/>
        </inertial>
    
</link>

<joint name="head_link_Eye_left_joint" type="revolute">
    <parent link="head_link"/>
    <child link="Eye_left"/>
    
      <origin xyz=" -0.7038  -0.3516   0.2422" rpy="  0.0000  -0.0000   0.0000" />

    <axis xyz="1 0 0"/>
    <!-- 
        THIS is a dirty hack must be fixed in future versions
        what we need is a new empty type which has properties for joint types limits...
        lower and upper could be set by constraints    
    -->
    <limit effort="0" velocity="0" lower="0" upper="0" />
  </joint> 
 
   <transmission name="head_link_Eye_left_trans">
      <type>transmission_interface/SimpleTransmission</type>
      <joint name="head_link_Eye_left_joint"/>
      <actuator name="head_link_Eye_left_motor">
          <hardwareInterface>PositionJointInterface</hardwareInterface>
         <mechanicalReduction>1</mechanicalReduction>
       </actuator>
  </transmission>

<link name="Eye_right">
    <!-- visual -->
    
    <visual>
        
        <geometry>
            <mesh filename="package://suzanne_robot_description/meshes/eye.dae"/>
        </geometry>
    </visual>

    
    <!-- collision -->
    
    <collision>
        
        <geometry>
            <mesh filename="package://suzanne_robot_description/meshes/eye.dae"/>
        </geometry>
    </collision>
    

    <!-- inertial -->
    
        <inertial>
        <origin xyz="0 0 0" rpy="3.14 0 0" />
        <mass value="1.5"/>
        <inertia 
            ixx="1.5" ixy="0.0" ixz="0.0" 
            iyy="1.5" iyz="0.0" 
            izz="1.5"/>
        </inertial>
    
</link>

<joint name="head_link_Eye_right_joint" type="revolute">
    <parent link="head_link"/>
    <child link="Eye_right"/>
    
      <origin xyz=" -0.7038   0.3516   0.2422" rpy="  0.0000  -0.0000   0.0000" />

    <axis xyz="1 0 0"/>
    <!-- 
        THIS is a dirty hack must be fixed in future versions
        what we need is a new empty type which has properties for joint types limits...
        lower and upper could be set by constraints    
    -->
    <limit effort="0" velocity="0" lower="0" upper="0" />
  </joint> 
 
   <transmission name="head_link_Eye_right_trans">
      <type>transmission_interface/SimpleTransmission</type>
      <joint name="head_link_Eye_right_joint"/>
      <actuator name="head_link_Eye_right_motor">
          <hardwareInterface>PositionJointInterface</hardwareInterface>
         <mechanicalReduction>1</mechanicalReduction>
       </actuator>
  </transmission>

<link name="Left_Back_Wheel">
    <!-- visual -->
    
    <visual>
        
        <geometry>
            <mesh filename="package://suzanne_robot_description/meshes/wheel.dae"/>
        </geometry>
    </visual>

    
    <!-- collision -->
    
    <collision>
        
        <geometry>
            <mesh filename="package://suzanne_robot_description/meshes/wheel.dae"/>
        </geometry>
    </collision>
    

    <!-- inertial -->
    
        <inertial>
        <origin xyz="0 0 0" rpy="0 0 0" />
        <mass value="5"/>
        <inertia 
            ixx="1.5" ixy="0.0" ixz="0.0" 
            iyy="1.5" iyz="0.0" 
            izz="1.5"/>
        </inertial>
    
</link>

<joint name="base_link_Left_Back_Wheel_joint" type="continuous">
    <parent link="base_link"/>
    <child link="Left_Back_Wheel"/>
    
      <origin xyz="  3.0000  -2.0000   0.0000" rpy="  0.0000  -0.0000   0.0000" />

    <axis xyz="0 1 0"/>
    <!-- 
        THIS is a dirty hack must be fixed in future versions
        what we need is a new empty type which has properties for joint types limits...
        lower and upper could be set by constraints    
    -->
    <limit effort="100" velocity="100" lower="-3.14" upper="3.14" />
  </joint> 
 
   <transmission name="base_link_Left_Back_Wheel_trans">
      <type>transmission_interface/SimpleTransmission</type>
      <joint name="base_link_Left_Back_Wheel_joint"/>
      <actuator name="base_link_Left_Back_Wheel_motor">
          <hardwareInterface>PositionJointInterface</hardwareInterface>
         <mechanicalReduction>1</mechanicalReduction>
       </actuator>
  </transmission>

<link name="Left_Front_Wheel">
    <!-- visual -->
    
    <visual>
        
        <geometry>
            <mesh filename="package://suzanne_robot_description/meshes/wheel.dae"/>
        </geometry>
    </visual>

    
    <!-- collision -->
    
    <collision>
        
        <geometry>
            <mesh filename="package://suzanne_robot_description/meshes/wheel.dae"/>
        </geometry>
    </collision>
        <inertial>
        <origin xyz="0 0 0" rpy="0 0 0" />
        <mass value="5"/>
        <inertia 
            ixx="1.5" ixy="0.0" ixz="0.0" 
            iyy="1.5" iyz="0.0" 
            izz="1.5"/>
        </inertial>
    
</link>

<joint name="base_link_Left_Front_Wheel_joint" type="continuous">
    <parent link="base_link"/>
    <child link="Left_Front_Wheel"/>
    
      <origin xyz=" -3.0000  -2.0000   0.0000" rpy="  0.0000  -0.0000   0.0000" />

    <axis xyz="0 1 0"/>
    <!-- 
        THIS is a dirty hack must be fixed in future versions
        what we need is a new empty type which has properties for joint types limits...
        lower and upper could be set by constraints    
    -->
    <limit effort="100" velocity="100" lower="-3.14" upper="3.14" />
  </joint> 
 
   <transmission name="base_link_Left_Front_Wheel_trans">
      <type>transmission_interface/SimpleTransmission</type>
      <joint name="base_link_Left_Front_Wheel_joint"/>
      <actuator name="base_link_Left_Front_Wheel_motor">
          <hardwareInterface>PositionJointInterface</hardwareInterface>
         <mechanicalReduction>1</mechanicalReduction>
       </actuator>
  </transmission>

<link name="Right_Back_Wheel">
    <!-- visual -->
    
    <visual>
        
        <geometry>
            <mesh filename="package://suzanne_robot_description/meshes/wheel.dae"/>
        </geometry>
    </visual>

    
    <!-- collision -->
    
    <collision>
        
        <geometry>
            <mesh filename="package://suzanne_robot_description/meshes/wheel.dae"/>
        </geometry>
    </collision>

    <!-- inertial -->
    
        <inertial>
        <origin xyz="0 0 0" rpy="0 0 0" />
        <mass value="5"/>
        <inertia 
            ixx="1.5" ixy="0.0" ixz="0.0" 
            iyy="1.5" iyz="0.0" 
            izz="1.5"/>
        </inertial>
    
</link>

<joint name="base_link_Right_Back_Wheel_joint" type="continuous">
    <parent link="base_link"/>
    <child link="Right_Back_Wheel"/>
    
      <origin xyz="  3.0000   2.0000   0.0000" rpy="  0.0000  -0.0000   0.0000" />

    <axis xyz="0 1 0"/>
    <!-- 
        THIS is a dirty hack must be fixed in future versions
        what we need is a new empty type which has properties for joint types limits...
        lower and upper could be set by constraints    
    -->
    <limit effort="100" velocity="100" lower="-3.14" upper="3.14" />
  </joint> 
 
   <transmission name="base_link_Right_Back_Wheel_trans">
      <type>transmission_interface/SimpleTransmission</type>
      <joint name="base_link_Right_Back_Wheel_joint"/>
      <actuator name="base_link_Right_Back_Wheel_motor">
          <hardwareInterface>PositionJointInterface</hardwareInterface>
         <mechanicalReduction>1</mechanicalReduction>
       </actuator>
  </transmission>

<link name="Right_Front_Wheel">
    <!-- visual -->
    
    <visual>
        
        <geometry>
            <mesh filename="package://suzanne_robot_description/meshes/wheel.dae"/>
        </geometry>
    </visual>

    
    <!-- collision -->
    
    <collision>
        
        <geometry>
            <mesh filename="package://suzanne_robot_description/meshes/wheel.dae"/>
        </geometry>
    </collision>

    <!-- inertial -->
   
        <inertial>
        <origin xyz="0 0 0" rpy="0 0 0" />
        <mass value="5"/>
        <inertia 
            ixx="1.5" ixy="0.0" ixz="0.0" 
            iyy="1.5" iyz="0.0" 
            izz="1.5"/>
        </inertial>
</link>

<joint name="base_link_Right_Front_Wheel_joint" type="continuous">
    <parent link="base_link"/>
    <child link="Right_Front_Wheel"/>
    
      <origin xyz=" -3.0000   2.0000   0.0000" rpy="  0.0000  -0.0000   0.0000" />

    <axis xyz="0 1 0"/>
    <!-- 
        THIS is a dirty hack must be fixed in future versions
        what we need is a new empty type which has properties for joint types limits...
        lower and upper could be set by constraints    
    -->
    <limit effort="100" velocity="100" lower="-3.14" upper="3.14" />
  </joint> 
 
   <transmission name="base_link_Right_Front_Wheel_trans">
      <type>transmission_interface/SimpleTransmission</type>
      <joint name="base_link_Right_Front_Wheel_joint"/>
      <actuator name="base_link_Right_Front_Wheel_motor">
          <hardwareInterface>PositionJointInterface</hardwareInterface>
         <mechanicalReduction>1</mechanicalReduction>
       </actuator>
  </transmission>

</robot>
